Workbook

Sheet 차량 DB
A1: 순번 | B1: 차량 번호 | C1: 시작일 | D1: 종료일 | E1: 그룹코드 | F1: 그룹명 | G1: 소유주 | H1: 연락처 | I1: 차종 | J1: 색상 | K1: 업체 | L1: 입차 홈넷 | M1: 출차 홈넷 | N1: 선택 요일제 | O1: 생산 공정 | P1: 생산 제품 1 | Q1: 생산 제품 2 | R1: 생산 제품 3 | S1: 부서 | T1: Scope | U1: 운행 목적 | V1: 주소 | W1: 주소(생략) | X1: 편도거리 (km) | Y1: 왕복거리 (km) | Z1: 운행 구분 | AA1: 차종 | AB1: 차종구분 (대분류) | AC1: 차종구분 (소분류) | AD1: 연료 종류 | AE1: 연비 (ℓ/km) | AF1: 탄소 배출 계수 | AG1: Co2 배출량 (kg)
A2: 1 | B2: 89주5842 | C2: 20240701 | D2: 20991231 | E2: 0001 | F2: 내부무료 | G2: 법인메가트럭(5T) | K2: 현대정밀 | L2: FALSE | M2: FALSE | N2: 없음 | S2: 납품 | T2: 1 | U2: 납품 | V2: 경남 창원시 성산구 귀현동 1번지 | X2: 13 | Y2: =X2*2 -> 26 | Z2: 13 | AA2: 메가트럭 | AB2: 상용 트럭 | AC2: 5t 급 | AD2: 디젤 | AE2: =IF(AB2="승용차", INDEX('연료 자료'!$C$6:$F$11, MATCH(AD2,'연료 자료'!$B$6:$B$11, 0), MATCH(AC2,'연료 자료'!$C$5:$F$5, 0)), INDEX('연료 자료'!$G$6:$I$11, MATCH(AD2,'연료 자료'!$B$6:$B$11, 0), MATCH(AC2,'연료 자료'!$G$5:$I$5, 0))) -> 5 | AF2: =VLOOKUP(AD2, 메모!$J$10:$L$19, 3, FALSE) -> 2.614 | AG2: =IF(Z2="왕복", Y2/AE2*AF2, X2/AE2*AF2) -> 6.7964
A3: 2 | B3: 86가3919 | C3: 20240701 | D3: 20991231 | E3: 0001 | F3: 내부무료 | G3: 법인 포터 | K3: 현대정밀 | L3: FALSE | M3: FALSE | N3: 없음 | S3: 납품 | T3: 1 | U3: 납품 | V3: 경남 창원시 성산구 귀현동 1번지 | X3: 13 | Y3: =X3*2 -> 26 | Z3: 13 | AA3: 포터2 | AB3: 상용 트럭 | AC3: 1t 급 | AD3: 디젤 | AE3: =IF(AB3="승용차", INDEX('연료 자료'!$C$6:$F$11, MATCH(AD3,'연료 자료'!$B$6:$B$11, 0), MATCH(AC3,'연료 자료'!$C$5:$F$5, 0)), INDEX('연료 자료'!$G$6:$I$11, MATCH(AD3,'연료 자료'!$B$6:$B$11, 0), MATCH(AC3,'연료 자료'!$G$5:$I$5, 0))) -> 9 | AF3: =VLOOKUP(AD3, 메모!$J$10:$L$19, 3, FALSE) -> 2.614 | AG3: =IF(Z3="왕복", Y3/AE3*AF3, X3/AE3*AF3) -> 3.7757778
A4: 3 | B4: 97가9808 | C4: 20240701 | D4: 20991231 | E4: 0001 | F4: 내부무료 | G4: 법인 메가트럭(5T) | K4: 현대정밀 | L4: FALSE | M4: FALSE | N4: 없음 | S4: 납품 | T4: 1 | U4: 납품 | V4: 경남 창원시 성산구 귀현동 1번지 | X4: 13 | Y4: =X4*2 -> 26 | Z4: 13 | AA4: 메가트럭 | AB4: 상용 트럭 | AC4: 5t 급 | AD4: 디젤 | AE4: =IF(AB4="승용차", INDEX('연료 자료'!$C$6:$F$11, MATCH(AD4,'연료 자료'!$B$6:$B$11, 0), MATCH(AC4,'연료 자료'!$C$5:$F$5, 0)), INDEX('연료 자료'!$G$6:$I$11, MATCH(AD4,'연료 자료'!$B$6:$B$11, 0), MATCH(AC4,'연료 자료'!$G$5:$I$5, 0))) -> 5 | AF4: =VLOOKUP(AD4, 메모!$J$10:$L$19, 3, FALSE) -> 2.614 | AG4: =IF(Z4="왕복", Y4/AE4*AF4, X4/AE4*AF4) -> 6.7964
A5: 4 | B5: 825너3484 | C5: 20240701 | D5: 20991231 | E5: 0001 | F5: 내부무료 | G5: 법인 봉고1T | K5: 현대정밀 | L5: FALSE | M5: FALSE | N5: 없음 | S5: 납품 | T5: 1 | U5: 납품 | V5: 경남 창원시 성산구 귀현동 1번지 | X5: 13 | Y5: =X5*2 -> 26 | Z5: 13 | AA5: 봉고3 | AB5: 상용 트럭 | AC5: 1t 급 | AD5: LPG | AE5: =IF(AB5="승용차", INDEX('연료 자료'!$C$6:$F$11, MATCH(AD5,'연료 자료'!$B$6:$B$11, 0), MATCH(AC5,'연료 자료'!$C$5:$F$5, 0)), INDEX('연료 자료'!$G$6:$I$11, MATCH(AD5,'연료 자료'!$B$6:$B$11, 0), MATCH(AC5,'연료 자료'!$G$5:$I$5, 0))) -> 5 | AF5: =VLOOKUP(AD5, 메모!$J$10:$L$19, 3, FALSE) -> 1.6 | AG5: =IF(Z5="왕복", Y5/AE5*AF5, X5/AE5*AF5) -> 4.16
A6: 8 | B6: 164구9626 | C6: 20240701 | D6: 20991231 | E6: 0001 | F6: 내부무료 | G6: 박종영 (법인) | K6: 현대정밀 | L6: FALSE | M6: FALSE | N6: 없음 | S6: 직원 | T6: 1 | U6: 출퇴근 | X6: 8 | Y6: =X6*2 -> 16 | Z6: 왕복 | AA6: 그렌져 | AB6: 승용차 | AC6: 대형 | AD6: 가솔린 | AE6: =IF(AB6="승용차", INDEX('연료 자료'!$C$6:$F$11, MATCH(AD6,'연료 자료'!$B$6:$B$11, 0), MATCH(AC6,'연료 자료'!$C$5:$F$5, 0)), INDEX('연료 자료'!$G$6:$I$11, MATCH(AD6,'연료 자료'!$B$6:$B$11, 0), MATCH(AC6,'연료 자료'!$G$5:$I$5, 0))) -> 7 | AF6: =VLOOKUP(AD6, 메모!$J$10:$L$19, 3, FALSE) -> 2.271 | AG6: =IF(Z6="왕복", Y6/AE6*AF6, X6/AE6*AF6) -> 5.1908571
A7: 9 | B7: 53머4356 | C7: 20240701 | D7: 20991231 | E7: 0001 | F7: 내부무료 | G7: 서경동 | K7: 현대정밀 | L7: FALSE | M7: FALSE | N7: 없음 | S7: 직원 | T7: 3 | U7: 출퇴근 | X7: 4.8 | Y7: =X7*2 -> 9.6 | Z7: 편도 | AA7: 스포티지 | AB7: 승용차 | AC7: 중형 | AD7: 디젤 | AE7: =IF(AB7="승용차", INDEX('연료 자료'!$C$6:$F$11, MATCH(AD7,'연료 자료'!$B$6:$B$11, 0), MATCH(AC7,'연료 자료'!$C$5:$F$5, 0)), INDEX('연료 자료'!$G$6:$I$11, MATCH(AD7,'연료 자료'!$B$6:$B$11, 0), MATCH(AC7,'연료 자료'!$G$5:$I$5, 0))) -> 13 | AF7: =VLOOKUP(AD7, 메모!$J$10:$L$19, 3, FALSE) -> 2.614 | AG7: =IF(Z7="왕복", Y7/AE7*AF7, X7/AE7*AF7) -> 0.96516923
A8: 10 | B8: 236가8159 | C8: 20240701 | D8: 20991231 | E8: 0001 | F8: 내부무료 | G8: 오은영 | K8: 현대정밀 | L8: FALSE | M8: FALSE | N8: 없음 | S8: 직원 | T8: 3 | U8: 출퇴근 | X8: 9.6 | Y8: =X8*2 -> 19.2 | Z8: 왕복 | AA8: 소나타 | AB8: 승용차 | AC8: 중형 | AD8: 가솔린 | AE8: =IF(AB8="승용차", INDEX('연료 자료'!$C$6:$F$11, MATCH(AD8,'연료 자료'!$B$6:$B$11, 0), MATCH(AC8,'연료 자료'!$C$5:$F$5, 0)), INDEX('연료 자료'!$G$6:$I$11, MATCH(AD8,'연료 자료'!$B$6:$B$11, 0), MATCH(AC8,'연료 자료'!$G$5:$I$5, 0))) -> 10 | AF8: =VLOOKUP(AD8, 메모!$J$10:$L$19, 3, FALSE) -> 2.271 | AG8: =IF(Z8="왕복", Y8/AE8*AF8, X8/AE8*AF8) -> 4.36032
A9: 11 | B9: 47다4577 | C9: 20240701 | D9: 20991231 | E9: 0001 | F9: 내부무료 | G9: 강병재 | K9: 현대정밀 | L9: FALSE | M9: FALSE | N9: 없음 | S9: 직원 | T9: 3 | U9: 출퇴근 | X9: 4.7 | Y9: =X9*2 -> 9.4 | Z9: 왕복 | AA9: i 40 | AB9: 승용차 | AC9: 소형 | AD9: 디젤 | AE9: =IF(AB9="승용차", INDEX('연료 자료'!$C$6:$F$11, MATCH(AD9,'연료 자료'!$B$6:$B$11, 0), MATCH(AC9,'연료 자료'!$C$5:$F$5, 0)), INDEX('연료 자료'!$G$6:$I$11, MATCH(AD9,'연료 자료'!$B$6:$B$11, 0), MATCH(AC9,'연료 자료'!$G$5:$I$5, 0))) -> 13 | AF9: =VLOOKUP(AD9, 메모!$J$10:$L$19, 3, FALSE) -> 2.614 | AG9: =IF(Z9="왕복", Y9/AE9*AF9, X9/AE9*AF9) -> 1.8901231
A10: 12 | B10: 157보9343 | C10: 20240701 | D10: 20991231 | E10: 0001 | F10: 내부무료 | G10: 윤대혁 | K10: 현대정밀 | L10: FALSE | M10: FALSE | N10: 없음 | S10: 직원 | T10: 3 | U10: 출퇴근 | X10: 9.3 | Y10: =X10*2 -> 18.6 | Z10: 왕복 | AA10: K7 | AB10: 승용차 | AC10: 중형 | AD10: 가솔린 | AE10: =IF(AB10="승용차", INDEX('연료 자료'!$C$6:$F$11, MATCH(AD10,'연료 자료'!$B$6:$B$11, 0), MATCH(AC10,'연료 자료'!$C$5:$F$5, 0)), INDEX('연료 자료'!$G$6:$I$11, MATCH(AD10,'연료 자료'!$B$6:$B$11, 0), MATCH(AC10,'연료 자료'!$G$5:$I$5, 0))) -> 10 | AF10: =VLOOKUP(AD10, 메모!$J$10:$L$19, 3, FALSE) -> 2.271 | AG10: =IF(Z10="왕복", Y10/AE10*AF10, X10/AE10*AF10) -> 4.22406
A11: 13 | B11: 28로8675 | C11: 20240701 | D11: 20991231 | E11: 0001 | F11: 내부무료 | G11: 황종욱 | K11: 현대정밀 | L11: FALSE | M11: FALSE | N11: 없음 | S11: 직원 | T11: 3 | U11: 출퇴근 | X11: 12 | Y11: =X11*2 -> 24 | Z11: 왕복 | AA11: 소나타 | AB11: 승용차 | AC11: 중형 | AD11: 가솔린 | AE11: =IF(AB11="승용차", INDEX('연료 자료'!$C$6:$F$11, MATCH(AD11,'연료 자료'!$B$6:$B$11, 0), MATCH(AC11,'연료 자료'!$C$5:$F$5, 0)), INDEX('연료 자료'!$G$6:$I$11, MATCH(AD11,'연료 자료'!$B$6:$B$11, 0), MATCH(AC11,'연료 자료'!$G$5:$I$5, 0))) -> 10 | AF11: =VLOOKUP(AD11, 메모!$J$10:$L$19, 3, FALSE) -> 2.271 | AG11: =IF(Z11="왕복", Y11/AE11*AF11, X11/AE11*AF11) -> 5.4504
A12: 14 | B12: 140라2920 | C12: 20240701 | D12: 20991231 | E12: 0001 | F12: 내부무료 | G12: 박호근1 | K12: 현대정밀 | L12: FALSE | M12: FALSE | N12: 없음 | S12: 직원 | T12: 3 | U12: 출퇴근 | X12: 5 | Y12: =X12*2 -> 10 | Z12: 왕복 | AA12: 스포티지 하이브리드 | AB12: 승용차 | AC12: 중형 | AD12: 하이브리드 | AE12: =IF(AB12="승용차", INDEX('연료 자료'!$C$6:$F$11, MATCH(AD12,'연료 자료'!$B$6:$B$11, 0), MATCH(AC12,'연료 자료'!$C$5:$F$5, 0)), INDEX('연료 자료'!$G$6:$I$11, MATCH(AD12,'연료 자료'!$B$6:$B$11, 0), MATCH(AC12,'연료 자료'!$G$5:$I$5, 0))) -> 15 | AF12: =VLOOKUP(AD12, 메모!$J$10:$L$19, 3, FALSE) -> 2.271 | AG12: =IF(Z12="왕복", Y12/AE12*AF12, X12/AE12*AF12) -> 1.514
A13: 15 | B13: 51너7263 | C13: 20240701 | D13: 20991231 | E13: 0001 | F13: 내부무료 | G13: 박호근2 | K13: 현대정밀 | L13: FALSE | M13: FALSE | N13: 없음 | S13: 직원 | T13: 3 | U13: 출퇴근 | X13: 5 | Y13: =X13*2 -> 10 | Z13: 왕복 | AA13: 모닝 | AB13: 승용차 | AC13: 경차 | AD13: 가솔린 | AE13: =IF(AB13="승용차", INDEX('연료 자료'!$C$6:$F$11, MATCH(AD13,'연료 자료'!$B$6:$B$11, 0), MATCH(AC13,'연료 자료'!$C$5:$F$5, 0)), INDEX('연료 자료'!$G$6:$I$11, MATCH(AD13,'연료 자료'!$B$6:$B$11, 0), MATCH(AC13,'연료 자료'!$G$5:$I$5, 0))) -> 14 | AF13: =VLOOKUP(AD13, 메모!$J$10:$L$19, 3, FALSE) -> 2.271 | AG13: =IF(Z13="왕복", Y13/AE13*AF13, X13/AE13*AF13) -> 1.6221429
A14: 16 | B14: 178구5586 | C14: 20240701 | D14: 20991231 | E14: 0001 | F14: 내부무료 | G14: 최시애 | K14: 현대정밀 | L14: FALSE | M14: FALSE | N14: 없음 | S14: 직원 | T14: 3 | U14: 출퇴근 | X14: 9.3 | Y14: =X14*2 -> 18.6 | Z14: 왕복 | AA14: 아반떼 | AB14: 승용차 | AC14: 소형 | AD14: 가솔린 | AE14: =IF(AB14="승용차", INDEX('연료 자료'!$C$6:$F$11, MATCH(AD14,'연료 자료'!$B$6:$B$11, 0), MATCH(AC14,'연료 자료'!$C$5:$F$5, 0)), INDEX('연료 자료'!$G$6:$I$11, MATCH(AD14,'연료 자료'!$B$6:$B$11, 0), MATCH(AC14,'연료 자료'!$G$5:$I$5, 0))) -> 12 | AF14: =VLOOKUP(AD14, 메모!$J$10:$L$19, 3, FALSE) -> 2.271 | AG14: =IF(Z14="왕복", Y14/AE14*AF14, X14/AE14*AF14) -> 3.52005
A15: 17 | B15: 62모0303 | C15: 20240701 | D15: 20991231 | E15: 0001 | F15: 내부무료 | G15: 김혜연 | K15: 현대정밀 | L15: FALSE | M15: FALSE | N15: 없음 | S15: 직원 | T15: 3 | U15: 출퇴근 | X15: 31 | Y15: =X15*2 -> 62 | Z15: 왕복 | AA15: 스파크 1.0 | AB15: 승용차 | AC15: 경차 | AD15: 가솔린 | AE15: =IF(AB15="승용차", INDEX('연료 자료'!$C$6:$F$11, MATCH(AD15,'연료 자료'!$B$6:$B$11, 0), MATCH(AC15,'연료 자료'!$C$5:$F$5, 0)), INDEX('연료 자료'!$G$6:$I$11, MATCH(AD15,'연료 자료'!$B$6:$B$11, 0), MATCH(AC15,'연료 자료'!$G$5:$I$5, 0))) -> 14 | AF15: =VLOOKUP(AD15, 메모!$J$10:$L$19, 3, FALSE) -> 2.271 | AG15: =IF(Z15="왕복", Y15/AE15*AF15, X15/AE15*AF15) -> 10.057286
A16: 18 | B16: 176보6996 | C16: 20240701 | D16: 20991231 | E16: 0001 | F16: 내부무료 | G16: 오권석 | K16: 현대정밀 | L16: FALSE | M16: FALSE | N16: 없음 | S16: 직원 | T16: 3 | U16: 출퇴근 | X16: 1.1 | Y16: =X16*2 -> 2.2 | Z16: 왕복 | AA16: 그렌져 | AB16: 승용차 | AC16: 대형 | AD16: 가솔린 | AE16: =IF(AB16="승용차", INDEX('연료 자료'!$C$6:$F$11, MATCH(AD16,'연료 자료'!$B$6:$B$11, 0), MATCH(AC16,'연료 자료'!$C$5:$F$5, 0)), INDEX('연료 자료'!$G$6:$I$11, MATCH(AD16,'연료 자료'!$B$6:$B$11, 0), MATCH(AC16,'연료 자료'!$G$5:$I$5, 0))) -> 7 | AF16: =VLOOKUP(AD16, 메모!$J$10:$L$19, 3, FALSE) -> 2.271 | AG16: =IF(Z16="왕복", Y16/AE16*AF16, X16/AE16*AF16) -> 0.71374286
A17: 19 | B17: 55노4224 | C17: 20240701 | D17: 20991231 | E17: 0001 | F17: 내부무료 | G17: 오윤석1 | K17: 현대정밀 | L17: FALSE | M17: FALSE | N17: 없음 | S17: 직원 | T17: 3 | U17: 출퇴근 | X17: 11 | Y17: =X17*2 -> 22 | Z17: 왕복 | AA17: 그렌져 | AB17: 승용차 | AC17: 대형 | AD17: 가솔린 | AE17: =IF(AB17="승용차", INDEX('연료 자료'!$C$6:$F$11, MATCH(AD17,'연료 자료'!$B$6:$B$11, 0), MATCH(AC17,'연료 자료'!$C$5:$F$5, 0)), INDEX('연료 자료'!$G$6:$I$11, MATCH(AD17,'연료 자료'!$B$6:$B$11, 0), MATCH(AC17,'연료 자료'!$G$5:$I$5, 0))) -> 7 | AF17: =VLOOKUP(AD17, 메모!$J$10:$L$19, 3, FALSE) -> 2.271 | AG17: =IF(Z17="왕복", Y17/AE17*AF17, X17/AE17*AF17) -> 7.1374286
... A23: 25 | B23: 298수4840 | C23: 20240701 | D23: 20991231 | E23: 0001 | F23: 내부무료 | G23: 이용하 | K23: 현대정밀 | L23: FALSE | M23: FALSE | N23: 없음 | S23: 직원 | T23: 3 | U23: 출퇴근 | X23: 4.1 | Y23: =X23*2 -> 8.2 | Z23: 왕복 | AA23: 소나타 | AB23: 승용차 | AC23: 중형 | AD23: 가솔린 | AE23: =IF(AB23="승용차", INDEX('연료 자료'!$C$6:$F$11, MATCH(AD23,'연료 자료'!$B$6:$B$11, 0), MATCH(AC23,'연료 자료'!$C$5:$F$5, 0)), INDEX('연료 자료'!$G$6:$I$11, MATCH(AD23,'연료 자료'!$B$6:$B$11, 0), MATCH(AC23,'연료 자료'!$G$5:$I$5, 0))) -> 10 | AF23: =VLOOKUP(AD23, 메모!$J$10:$L$19, 3, FALSE) -> 2.271 | AG23: =IF(Z23="왕복", Y23/AE23*AF23, X23/AE23*AF23) -> 1.86222
A24: 26 | B24: 41서1458 | C24: 20240701 | D24: 20991231 | E24: 0001 | F24: 내부무료 | G24: 최성우 | I24: 승용 | K24: 현대정밀 | L24: FALSE | M24: FALSE | N24: 없음 | S24: 직원 | T24: 3 | U24: 출퇴근 | X24: 8.2 | Y24: =X24*2 -> 16.4 | Z24: 왕복 | AA24: SM5 | AB24: 승용차 | AC24: 중형 | AD24: 가솔린 | AE24: =IF(AB24="승용차", INDEX('연료 자료'!$C$6:$F$11, MATCH(AD24,'연료 자료'!$B$6:$B$11, 0), MATCH(AC24,'연료 자료'!$C$5:$F$5, 0)), INDEX('연료 자료'!$G$6:$I$11, MATCH(AD24,'연료 자료'!$B$6:$B$11, 0), MATCH(AC24,'연료 자료'!$G$5:$I$5, 0))) -> 10 | AF24: =VLOOKUP(AD24, 메모!$J$10:$L$19, 3, FALSE) -> 2.271 | AG24: =IF(Z24="왕복", Y24/AE24*AF24, X24/AE24*AF24) -> 3.72444
A25: 27 | B25: 139두1461 | C25: 20240701 | D25: 20991231 | E25: 0001 | F25: 내부무료 | G25: 박길석 | I25: 승용 | K25: 현대정밀 | L25: FALSE | M25: FALSE | N25: 없음 | S25: 직원 | T25: 3 | U25: 출퇴근 | X25: 16 | Y25: =X25*2 -> 32 | Z25: 왕복 | AA25: 아반떼 | AB25: 승용차 | AC25: 소형 | AD25: 가솔린 | AE25: =IF(AB25="승용차", INDEX('연료 자료'!$C$6:$F$11, MATCH(AD25,'연료 자료'!$B$6:$B$11, 0), MATCH(AC25,'연료 자료'!$C$5:$F$5, 0)), INDEX('연료 자료'!$G$6:$I$11, MATCH(AD25,'연료 자료'!$B$6:$B$11, 0), MATCH(AC25,'연료 자료'!$G$5:$I$5, 0))) -> 12 | AF25: =VLOOKUP(AD25, 메모!$J$10:$L$19, 3, FALSE) -> 2.271 | AG25: =IF(Z25="왕복", Y25/AE25*AF25, X25/AE25*AF25) -> 6.056
A26: 28 | B26: 52우2160 | C26: 20240701 | D26: 20991231 | E26: 0001 | F26: 내부무료 | G26: 김봉진 | K26: 현대정밀 | L26: FALSE | M26: FALSE | N26: 없음 | S26: 직원 | T26: 3 | U26: 출퇴근 | X26: 11 | Y26: =X26*2 -> 22 | Z26: 왕복 | AA26: K5 | AB26: 승용차 | AC26: 중형 | AD26: 가솔린 | AE26: =IF(AB26="승용차", INDEX('연료 자료'!$C$6:$F$11, MATCH(AD26,'연료 자료'!$B$6:$B$11, 0), MATCH(AC26,'연료 자료'!$C$5:$F$5, 0)), INDEX('연료 자료'!$G$6:$I$11, MATCH(AD26,'연료 자료'!$B$6:$B$11, 0), MATCH(AC26,'연료 자료'!$G$5:$I$5, 0))) -> 10 | AF26: =VLOOKUP(AD26, 메모!$J$10:$L$19, 3, FALSE) -> 2.271 | AG26: =IF(Z26="왕복", Y26/AE26*AF26, X26/AE26*AF26) -> 4.9962
A27: 29 | B27: 30러4803 | C27: 20240701 | D27: 20991231 | E27: 0001 | F27: 내부무료 | G27: 임헌규 | I27: SUV | K27: 현대정밀 | L27: FALSE | M27: FALSE | N27: 없음 | S27: 직원 | T27: 3 | U27: 출퇴근 | X27: 31 | Y27: =X27*2 -> 62 | Z27: 왕복 | AA27: 스포티지 | AB27: 승용차 | AC27: 중형 | AD27: 가솔린 | AE27: =IF(AB27="승용차", INDEX('연료 자료'!$C$6:$F$11, MATCH(AD27,'연료 자료'!$B$6:$B$11, 0), MATCH(AC27,'연료 자료'!$C$5:$F$5, 0)), INDEX('연료 자료'!$G$6:$I$11, MATCH(AD27,'연료 자료'!$B$6:$B$11, 0), MATCH(AC27,'연료 자료'!$G$5:$I$5, 0))) -> 10 | AF27: =VLOOKUP(AD27, 메모!$J$10:$L$19, 3, FALSE) -> 2.271 | AG27: =IF(Z27="왕복", Y27/AE27*AF27, X27/AE27*AF27) -> 14.0802
A28: 30 | B28: 03노3595 | C28: 20240701 | D28: 20991231 | E28: 0001 | F28: 내부무료 | G28: 김영수1 | I28: SUV | K28: 현대정밀 | L28: FALSE | M28: FALSE | N28: 없음 | S28: 직원 | T28: 3 | U28: 출퇴근 | X28: 6.9 | Y28: =X28*2 -> 13.8 | Z28: 왕복 | AA28: 쏘렌토 | AB28: 승용차 | AC28: 중형 | AD28: 디젤 | AE28: =IF(AB28="승용차", INDEX('연료 자료'!$C$6:$F$11, MATCH(AD28,'연료 자료'!$B$6:$B$11, 0), MATCH(AC28,'연료 자료'!$C$5:$F$5, 0)), INDEX('연료 자료'!$G$6:$I$11, MATCH(AD28,'연료 자료'!$B$6:$B$11, 0), MATCH(AC28,'연료 자료'!$G$5:$I$5, 0))) -> 13 | AF28: =VLOOKUP(AD28, 메모!$J$10:$L$19, 3, FALSE) -> 2.614 | AG28: =IF(Z28="왕복", Y28/AE28*AF28, X28/AE28*AF28) -> 2.7748615
A29: 31 | B29: 24노5922 | C29: 20240701 | D29: 20991231 | E29: 0001 | F29: 내부무료 | G29: 김영수2 | I29: SUV | K29: 현대정밀 | L29: FALSE | M29: FALSE | N29: 없음 | S29: 직원 | T29: 3 | U29: 출퇴근 | X29: 6.9 | Y29: =X29*2 -> 13.8 | Z29: 왕복 | AA29: 스파크 1.0 | AB29: 승용차 | AC29: 경차 | AD29: 가솔린 | AE29: =IF(AB29="승용차", INDEX('연료 자료'!$C$6:$F$11, MATCH(AD29,'연료 자료'!$B$6:$B$11, 0), MATCH(AC29,'연료 자료'!$C$5:$F$5, 0)), INDEX('연료 자료'!$G$6:$I$11, MATCH(AD29,'연료 자료'!$B$6:$B$11, 0), MATCH(AC29,'연료 자료'!$G$5:$I$5, 0))) -> 14 | AF29: =VLOOKUP(AD29, 메모!$J$10:$L$19, 3, FALSE) -> 2.271 | AG29: =IF(Z29="왕복", Y29/AE29*AF29, X29/AE29*AF29) -> 2.2385571
A30: 32 | B30: 97라0824 | C30: 20240701 | D30: 20991231 | E30: 0001 | F30: 내부무료 | G30: 김성태 | I30: 트럭 | K30: 현대정밀 | L30: FALSE | M30: FALSE | N30: 없음 | S30: 직원 | T30: 3 | U30: 출퇴근 | X30: 6.5 | Y30: =X30*2 -> 13 | Z30: 왕복 | AA30: 봉고3 1톤 | AB30: 상용 트럭 | AC30: 1t 급 | AD30: 디젤 | AE30: =IF(AB30="승용차", INDEX('연료 자료'!$C$6:$F$11, MATCH(AD30,'연료 자료'!$B$6:$B$11, 0), MATCH(AC30,'연료 자료'!$C$5:$F$5, 0)), INDEX('연료 자료'!$G$6:$I$11, MATCH(AD30,'연료 자료'!$B$6:$B$11, 0), MATCH(AC30,'연료 자료'!$G$5:$I$5, 0))) -> 9 | AF30: =VLOOKUP(AD30, 메모!$J$10:$L$19, 3, FALSE) -> 2.614 | AG30: =IF(Z30="왕복", Y30/AE30*AF30, X30/AE30*AF30) -> 3.7757778
A31: 33 | B31: 281다3241 | C31: 20240701 | D31: 20991231 | E31: 0001 | F31: 내부무료 | G31: 박상용1 | K31: 현대정밀 | L31: FALSE | M31: FALSE | N31: 없음 | S31: 직원 | T31: 3 | U31: 출퇴근 | X31: 22 | Y31: =X31*2 -> 44 | Z31: 왕복 | AA31: 베라크루즈 | AB31: 승용차 | AC31: 대형 | AD31: 디젤 | AE31: =IF(AB31="승용차", INDEX('연료 자료'!$C$6:$F$11, MATCH(AD31,'연료 자료'!$B$6:$B$11, 0), MATCH(AC31,'연료 자료'!$C$5:$F$5, 0)), INDEX('연료 자료'!$G$6:$I$11, MATCH(AD31,'연료 자료'!$B$6:$B$11, 0), MATCH(AC31,'연료 자료'!$G$5:$I$5, 0))) -> 10 | AF31: =VLOOKUP(AD31, 메모!$J$10:$L$19, 3, FALSE) -> 2.614 | AG31: =IF(Z31="왕복", Y31/AE31*AF31, X31/AE31*AF31) -> 11.5016
A32: 34 | B32: 17보5519 | C32: 20240701 | D32: 20991231 | E32: 0001 | F32: 내부무료 | G32: 박상용2 | K32: 현대정밀 | L32: FALSE | M32: FALSE | N32: 없음 | S32: 직원 | T32: 3 | U32: 출퇴근 | X32: 22 | Y32: =X32*2 -> 44 | Z32: 왕복 | AA32: SM5 LPG | AB32: 승용차 | AC32: 중형 | AD32: LPG | AE32: =IF(AB32="승용차", INDEX('연료 자료'!$C$6:$F$11, MATCH(AD32,'연료 자료'!$B$6:$B$11, 0), MATCH(AC32,'연료 자료'!$C$5:$F$5, 0)), INDEX('연료 자료'!$G$6:$I$11, MATCH(AD32,'연료 자료'!$B$6:$B$11, 0), MATCH(AC32,'연료 자료'!$G$5:$I$5, 0))) -> 7 | AF32: =VLOOKUP(AD32, 메모!$J$10:$L$19, 3, FALSE) -> 1.6 | AG32: =IF(Z32="왕복", Y32/AE32*AF32, X32/AE32*AF32) -> 10.057143
A33: 35 | B33: 42더5799 | C33: 20240701 | D33: 20991231 | E33: 0001 | F33: 내부무료 | G33: 손정익 | I33: SUV | K33: 현대정밀 | L33: FALSE | M33: FALSE | N33: 없음 | S33: 직원 | T33: 3 | U33: 출퇴근 | X33: 0.9 | Y33: =X33*2 -> 1.8 | Z33: 왕복 | AA33: 스포티지 | AB33: 승용차 | AC33: 중형 | AD33: 가솔린 | AE33: =IF(AB33="승용차", INDEX('연료 자료'!$C$6:$F$11, MATCH(AD33,'연료 자료'!$B$6:$B$11, 0), MATCH(AC33,'연료 자료'!$C$5:$F$5, 0)), INDEX('연료 자료'!$G$6:$I$11, MATCH(AD33,'연료 자료'!$B$6:$B$11, 0), MATCH(AC33,'연료 자료'!$G$5:$I$5, 0))) -> 10 | AF33: =VLOOKUP(AD33, 메모!$J$10:$L$19, 3, FALSE) -> 2.271 | AG33: =IF(Z33="왕복", Y33/AE33*AF33, X33/AE33*AF33) -> 0.40878
A34: 36 | B34: 55더9687 | C34: 20240701 | D34: 20991231 | E34: 0001 | F34: 내부무료 | G34: 이도경 | K34: 현대정밀 | L34: FALSE | M34: FALSE | N34: 없음 | S34: 직원 | T34: 3 | U34: 출퇴근 | X34: 9.9 | Y34: =X34*2 -> 19.8 | Z34: 왕복 | AA34: 카니발 리무진 | AB34: 승용차 | AC34: 대형 | AD34: 가솔린 | AE34: =IF(AB34="승용차", INDEX('연료 자료'!$C$6:$F$11, MATCH(AD34,'연료 자료'!$B$6:$B$11, 0), MATCH(AC34,'연료 자료'!$C$5:$F$5, 0)), INDEX('연료 자료'!$G$6:$I$11, MATCH(AD34,'연료 자료'!$B$6:$B$11, 0), MATCH(AC34,'연료 자료'!$G$5:$I$5, 0))) -> 7 | AF34: =VLOOKUP(AD34, 메모!$J$10:$L$19, 3, FALSE) -> 2.271 | AG34: =IF(Z34="왕복", Y34/AE34*AF34, X34/AE34*AF34) -> 6.4236857
A35: 37 | B35: 18누5875 | C35: 20240701 | D35: 20991231 | E35: 0001 | F35: 내부무료 | G35: 박성환 | K35: 현대정밀 | L35: FALSE | M35: FALSE | N35: 없음 | S35: 직원 | T35: 3 | U35: 출퇴근 | X35: 11 | Y35: =X35*2 -> 22 | Z35: 왕복 | AA35: SM7 | AB35: 승용차 | AC35: 중형 | AD35: 가솔린 | AE35: =IF(AB35="승용차", INDEX('연료 자료'!$C$6:$F$11, MATCH(AD35,'연료 자료'!$B$6:$B$11, 0), MATCH(AC35,'연료 자료'!$C$5:$F$5, 0)), INDEX('연료 자료'!$G$6:$I$11, MATCH(AD35,'연료 자료'!$B$6:$B$11, 0), MATCH(AC35,'연료 자료'!$G$5:$I$5, 0))) -> 10 | AF35: =VLOOKUP(AD35, 메모!$J$10:$L$19, 3, FALSE) -> 2.271 | AG35: =IF(Z35="왕복", Y35/AE35*AF35, X35/AE35*AF35) -> 4.9962
A36: 38 | B36: 32루6509 | C36: 20240701 | D36: 20991231 | E36: 0001 | F36: 내부무료 | G36: 오형동 | I36: 승용 | K36: 현대정밀 | L36: FALSE | M36: FALSE | N36: 없음 | S36: 직원 | T36: 3 | U36: 출퇴근 | X36: 11 | Y36: =X36*2 -> 22 | Z36: 왕복 | AA36: SM3 | AB36: 승용차 | AC36: 소형 | AD36: 가솔린 | AE36: =IF(AB36="승용차", INDEX('연료 자료'!$C$6:$F$11, MATCH(AD36,'연료 자료'!$B$6:$B$11, 0), MATCH(AC36,'연료 자료'!$C$5:$F$5, 0)), INDEX('연료 자료'!$G$6:$I$11, MATCH(AD36,'연료 자료'!$B$6:$B$11, 0), MATCH(AC36,'연료 자료'!$G$5:$I$5, 0))) -> 12 | AF36: =VLOOKUP(AD36, 메모!$J$10:$L$19, 3, FALSE) -> 2.271 | AG36: =IF(Z36="왕복", Y36/AE36*AF36, X36/AE36*AF36) -> 4.1635
A37: 39 | B37: 경남33고2725 | C37: 20240701 | D37: 20991231 | E37: 0001 | F37: 내부무료 | G37: 구성계 | I37: 승용 | K37: 현대정밀 | L37: FALSE | M37: FALSE | N37: 없음 | S37: 직원 | T37: 3 | U37: 출퇴근 | X37: 11 | Y37: =X37*2 -> 22 | Z37: 왕복 | AA37: 그렌져 | AB37: 승용차 | AC37: 대형 | AD37: 가솔린 | AE37: =IF(AB37="승용차", INDEX('연료 자료'!$C$6:$F$11, MATCH(AD37,'연료 자료'!$B$6:$B$11, 0), MATCH(AC37,'연료 자료'!$C$5:$F$5, 0)), INDEX('연료 자료'!$G$6:$I$11, MATCH(AD37,'연료 자료'!$B$6:$B$11, 0), MATCH(AC37,'연료 자료'!$G$5:$I$5, 0))) -> 7 | AF37: =VLOOKUP(AD37, 메모!$J$10:$L$19, 3, FALSE) -> 2.271 | AG37: =IF(Z37="왕복", Y37/AE37*AF37, X37/AE37*AF37) -> 7.1374286
A38: 184 | B38: 146너2950 | C38: 20241101 | D38: 20991231 | E38: 0001 | F38: 내부무료 | G38: 최시애2 | K38: 현대정밀 | L38: FALSE | M38: FALSE | N38: 없음 | S38: 직원 | T38: 3 | U38: 출퇴근 | X38: 9.3 | Y38: =X38*2 -> 18.6 | AA38: 소나타 | AB38: 승용차 | AC38: 중형 | AD38: 가솔린 | AE38: =IF(AB38="승용차", INDEX('연료 자료'!$C$6:$F$11, MATCH(AD38,'연료 자료'!$B$6:$B$11, 0), MATCH(AC38,'연료 자료'!$C$5:$F$5, 0)), INDEX('연료 자료'!$G$6:$I$11, MATCH(AD38,'연료 자료'!$B$6:$B$11, 0), MATCH(AC38,'연료 자료'!$G$5:$I$5, 0))) -> 10 | AF38: =VLOOKUP(AD38, 메모!$J$10:$L$19, 3, FALSE) -> 2.271 | AG38: =IF(Z38="왕복", Y38/AE38*AF38, X38/AE38*AF38) -> 2.11203
A39: 158 | B39: 57로3919 | C39: 20240901 | D39: 20991231 | E39: 0001 | F39: 내부무료 | G39: 오상준 | K39: 현대정밀 | L39: FALSE | M39: FALSE | N39: 없음 | S39: 직원 | T39: 3 | U39: 출퇴근 | X39: 13 | Y39: =X39*2 -> 26 | AA39: K3 | AB39: 승용차 | AC39: 소형 | AD39: 가솔린 | AE39: =IF(AB39="승용차", INDEX('연료 자료'!$C$6:$F$11, MATCH(AD39,'연료 자료'!$B$6:$B$11, 0), MATCH(AC39,'연료 자료'!$C$5:$F$5, 0)), INDEX('연료 자료'!$G$6:$I$11, MATCH(AD39,'연료 자료'!$B$6:$B$11, 0), MATCH(AC39,'연료 자료'!$G$5:$I$5, 0))) -> 12 | AF39: =VLOOKUP(AD39, 메모!$J$10:$L$19, 3, FALSE) -> 2.271 | AG39: =IF(Z39="왕복", Y39/AE39*AF39, X39/AE39*AF39) -> 2.46025
A40: 159 | B40: 254소5194 | C40: 20240901 | D40: 20991231 | E40: 0001 | F40: 내부무료 | G40: 강원근 | K40: 현대정밀 | L40: FALSE | M40: FALSE | N40: 없음 | S40: 직원 | T40: 3 | U40: 출퇴근 | X40: 3.5 | Y40: =X40*2 -> 7 | AA40: 셀토스 | AB40: 승용차 | AC40: 소형 | AD40: 가솔린 | AE40: =IF(AB40="승용차", INDEX('연료 자료'!$C$6:$F$11, MATCH(AD40,'연료 자료'!$B$6:$B$11, 0), MATCH(AC40,'연료 자료'!$C$5:$F$5, 0)), INDEX('연료 자료'!$G$6:$I$11, MATCH(AD40,'연료 자료'!$B$6:$B$11, 0), MATCH(AC40,'연료 자료'!$G$5:$I$5, 0))) -> 12 | AF40: =VLOOKUP(AD40, 메모!$J$10:$L$19, 3, FALSE) -> 2.271 | AG40: =IF(Z40="왕복", Y40/AE40*AF40, X40/AE40*AF40) -> 0.662375
A41: 179 | B41: 143우3855 | C41: 20241101 | D41: 20991231 | E41: 0001 | F41: 내부무료 | G41: 이미영 부장님 | K41: 현대정밀 | L41: FALSE | M41: FALSE | N41: 없음 | S41: 직원 | T41: 3 | U41: 출퇴근 | X41: 8.6 | Y41: =X41*2 -> 17.2 | AA41: 소나타 | AB41: 승용차 | AC41: 중형 | AD41: 가솔린 | AE41: =IF(AB41="승용차", INDEX('연료 자료'!$C$6:$F$11, MATCH(AD41,'연료 자료'!$B$6:$B$11, 0), MATCH(AC41,'연료 자료'!$C$5:$F$5, 0)), INDEX('연료 자료'!$G$6:$I$11, MATCH(AD41,'연료 자료'!$B$6:$B$11, 0), MATCH(AC41,'연료 자료'!$G$5:$I$5, 0))) -> 10 | AF41: =VLOOKUP(AD41, 메모!$J$10:$L$19, 3, FALSE) -> 2.271 | AG41: =IF(Z41="왕복", Y41/AE41*AF41, X41/AE41*AF41) -> 1.95306
A42: 211 | B42: 97라0877 | C42: 20250301 | D42: 20991231 | E42: 0001 | F42: 내부무료 | G42: 서창렬 | I42: 트럭 | K42: 현대정밀 | L42: FALSE | M42: FALSE | N42: 없음 | S42: 직원 | T42: 3 | U42: 출퇴근 | X42: 6.8 | Y42: =X42*2 -> 13.6 | AA42: 봉고3 | AB42: 상용 트럭 | AC42: 1t 급 | AD42: 디젤 | AE42: =IF(AB42="승용차", INDEX('연료 자료'!$C$6:$F$11, MATCH(AD42,'연료 자료'!$B$6:$B$11, 0), MATCH(AC42,'연료 자료'!$C$5:$F$5, 0)), INDEX('연료 자료'!$G$6:$I$11, MATCH(AD42,'연료 자료'!$B$6:$B$11, 0), MATCH(AC42,'연료 자료'!$G$5:$I$5, 0))) -> 9 | AF42: =VLOOKUP(AD42, 메모!$J$10:$L$19, 3, FALSE) -> 2.614 | AG42: =IF(Z42="왕복", Y42/AE42*AF42, X42/AE42*AF42) -> 1.9750222
A43: 213 | B43: 63로2956 | C43: 20250301 | D43: 20991231 | E43: 0001 | F43: 내부무료 | G43: 강원근 5 | I43: 승용 | K43: 현대정밀 | L43: FALSE | M43: FALSE | N43: 없음 | S43: 직원 | T43: 3 | U43: 출퇴근 | X43: 3.5 | Y43: =X43*2 -> 7 | AA43: Golf 2.0 GTI | AB43: 승용차 | AC43: 중형 | AD43: 가솔린 | AE43: =IF(AB43="승용차", INDEX('연료 자료'!$C$6:$F$11, MATCH(AD43,'연료 자료'!$B$6:$B$11, 0), MATCH(AC43,'연료 자료'!$C$5:$F$5, 0)), INDEX('연료 자료'!$G$6:$I$11, MATCH(AD43,'연료 자료'!$B$6:$B$11, 0), MATCH(AC43,'연료 자료'!$G$5:$I$5, 0))) -> 10 | AF43: =VLOOKUP(AD43, 메모!$J$10:$L$19, 3, FALSE) -> 2.271 | AG43: =IF(Z43="왕복", Y43/AE43*AF43, X43/AE43*AF43) -> 0.79485
A44: 219 | B44: 14구2295 | C44: 20250501 | D44: 20991231 | E44: 0001 | F44: 내부무료 | G44: 정경태 3 | K44: 현대정밀 | L44: FALSE | M44: FALSE | N44: 없음 | S44: 직원 | T44: 3 | U44: 출퇴근 | X44: 3.8 | Y44: =X44*2 -> 7.6 | AA44: 모닝 | AB44: 승용차 | AC44: 경차 | AD44: 가솔린 | AE44: =IF(AB44="승용차", INDEX('연료 자료'!$C$6:$F$11, MATCH(AD44,'연료 자료'!$B$6:$B$11, 0), MATCH(AC44,'연료 자료'!$C$5:$F$5, 0)), INDEX('연료 자료'!$G$6:$I$11, MATCH(AD44,'연료 자료'!$B$6:$B$11, 0), MATCH(AC44,'연료 자료'!$G$5:$I$5, 0))) -> 14 | AF44: =VLOOKUP(AD44, 메모!$J$10:$L$19, 3, FALSE) -> 2.271 | AG44: =IF(Z44="왕복", Y44/AE44*AF44, X44/AE44*AF44) -> 0.61641429
A45: 221 | B45: 385구2983 | C45: 20250501 | D45: 20991231 | E45: 0001 | F45: 내부무료 | G45: 양현진 | K45: 현대정밀 | L45: FALSE | M45: FALSE | N45: 없음 | S45: 직원 | T45: 3 | U45: 출퇴근 | X45: 14 | Y45: =X45*2 -> 28 | AA45: 셀토스 | AB45: 승용차 | AC45: 대형 | AD45: 가솔린 | AE45: =IF(AB45="승용차", INDEX('연료 자료'!$C$6:$F$11, MATCH(AD45,'연료 자료'!$B$6:$B$11, 0), MATCH(AC45,'연료 자료'!$C$5:$F$5, 0)), INDEX('연료 자료'!$G$6:$I$11, MATCH(AD45,'연료 자료'!$B$6:$B$11, 0), MATCH(AC45,'연료 자료'!$G$5:$I$5, 0))) -> 7 | AF45: =VLOOKUP(AD45, 메모!$J$10:$L$19, 3, FALSE) -> 2.271 | AG45: =IF(Z45="왕복", Y45/AE45*AF45, X45/AE45*AF45) -> 4.542
...

Sheet 연료 자료
H2: 승용차는 연비 중간 수준- 검토
B3: 차종, 연료 종류별 연비 정보
B4: 구분 | C4: 승용차 | G4: 상용 트럭
C5: 경차 | D5: 소형 | E5: 중형 | F5: 대형 | G5: 1t 급 | H5: 5t 급 | I5: 8t 이상
B6: 가솔린 | C6: 14 | D6: 12 | E6: 10 | F6: 7 | G6: - | H6: - | I6: -
B7: 디젤 | C7: 13 | D7: 13 | E7: 13 | F7: 10 | G7: 9 | H7: 5 | I7: 3
B8: 하이브리드 | C8: 15 | D8: 15 | E8: 15 | F8: 15 | G8: - | H8: - | I8: -
B9: LPG | C9: 7 | D9: 7 | E9: 7 | F9: 7 | G9: 5 | H9: - | I9: -
B10: 전기 | C10: 5 | D10: 5 | E10: 5 | F10: 5 | G10: 5 | H10: - | I10: -
B11: 수소 | C11: 100 | D11: 100 | E11: 100 | F11: 100 | G11: - | H11: - | I11: -
I12: ※ 각 연료량은 연료별로 상이 (아래내용 참조)
B15: 연료 계산 | C15: =IF(#REF!="승용차", INDEX(C6:F11, MATCH(#REF!, B6:B11, 0), MATCH(#REF!,C5:F5, 0)), INDEX(G6:I11, MATCH(#REF!, B6:B11, 0), MATCH(#REF!, G5:I5, 0))) -> #REF!
B19: 연료별 연비 정보
B21: 구분 | C21: 연비 정보 | H21: 비고
B22: 가솔린 | C22: ℓ (연료량) / km(거리)
B23: 디젤 | C23: ℓ (연료량) / km(거리)
B24: 하이브리드 | C24: ℓ (연료량) / km(거리)
B25: LPG | C25: ℓ (연료량) / km(거리)
B26: 전기 | C26: km(거리) / kWh (전력량)
B27: 수소 | C27: km(거리) / kg (수소량)
B29: 주요 연료별 탄소 배출 계수 (2024년 기준)
B31: 연료종류 | D31: 단위 | E31: CO₂ 배출계수 (kg CO₂ / 단위) | G31: 비고
B32: 가솔린 | D32: L당 | E32: 2.271 kg CO₂/L | G32: 자동차용 일반 휘발유
B33: 디젤 | D33: L당 | E33: 2.614 kg CO₂/L | G33: 디젤 차량, 상용차 등
B34: LPG | D34: L당 | E34: 1.600 kg CO₂/L | G34: 택시, 승용, 소형트럭 (액화 석유 가스)
B35: CNG | D35: Nm³당 | E35: 2.000 kg CO₂/Nm³ | G35: 버스, 청소차 등 공공차량 (압축 천연 가스)
B36: 수소 | D36: kg당 | E36: 0 kg CO₂/kg 사용단계 기준 | G36: 다만 생산단계에서 CO₂ 발생 가능
B37: 전기 | D37: kWh당 | E37: 0.425 kg CO₂/kWh | G37: 한국전력 2024년 평균 전력배출계수 기준
B38: 중유 (Bunker C 등) | D38: L당 | E38: 2.991 kg CO₂/L | G38: 산업·선박용, 대형엔진용
B39: 등유 (Kerosene) | D39: L당 | E39: 2.514 kg CO₂/L | G39: 난방용·항공기용
B40: 도시가스 (LNG) | D40: Nm³당 | E40: 2.003 kg CO₂/Nm³ | G40: 고정연소 기준 (천연가스 동일계수)

Sheet 탄소배출 공식

Sheet 메모
A2: 1 | B2: 차종
A3: 2 | B3: 차종별 연비
A4: 3
B8: 차종별 연비 | J8: 차량 주요 연료별 탄수 배출 계수 (환경부 2024년 기준)
C9: 차량 종류 | D9: 연료 | E9: 평균 연비 (km/L) | F9: 비고 | J9: 연료 종류 | K9: 단위 | L9: CO₂ 배출계수 (kg CO₂ / 단위) | M9: 비고
C10: 경차 (예: 모닝, 스파크) | D10: 휘발유 | E10: 14~17 | F10: 도심 주행에 유리 | J10: 가솔린 | K10: L당 | L10: 2.271 | M10: 자동차용 일반 휘발유
C11: 소형차 (예: 아반떼, K3) | D11: 휘발유 | E11: 12~16 | F11: 일반적인 세단 | J11: 디젤 | K11: L당 | L11: 2.614 | M11: 디젤 차량, 상용차 등
C12: 중형차 (예: 쏘나타, K5) | D12: 휘발유 | E12: 10~14 | F12: 배기량 1.6~2.0L 수준 | J12: LPG | K12: L당 | L12: 1.6 | M12: 택시, 승용, 소형트럭
C13: 대형차 (예: 그랜저, G80) | D13: 휘발유 | E13: 7~11 | F13: 무게와 배기량 영향 큼 | J13: CNG | K13: Nm³당 | L13: 2 | M13: 버스, 청소차 등 공공차량
C14: SUV (소형~중형) | D14: 휘발유/경유 | E14: 8~14 | F14: 4WD는 연비 더 낮음 | J14: 수소 | K14: kg당 | L14: 0 | M14: 다만 생산단계에서 CO₂ 발생 가능
C15: 디젤 승용차 | D15: 경유 | E15: 13~18 | F15: 고속도로 효율 우수 | J15: 전기 | K15: kWh당 | L15: 0.425 | M15: 한국전력 2024년 평균 전력배출계수 기준
C16: 스포츠카 / 고성능차 | D16: 휘발유 | E16: 6~10 | F16: 출력 중심 설계 | J16: 중유 (Bunker C 등) | K16: L당 | L16: 2.991 | M16: 산업·선박용, 대형엔진용
J17: 등유 (Kerosene) | K17: L당 | L17: 2.514 | M17: 난방용·항공기용
J18: 도시가스 (LNG) | K18: Nm³당 | L18: 2.003 | M18: 고정연소 기준 (천연가스 동일계수)
C19: 소형~중형 하이브리드 (예: 아반떼 HEV, K5 HEV) | D19: - | E19: 18~22 | F19: 도심 주행 효율 매우 높음 | J19: 하이브리드 | K19: L당 | L19: 2.271 | M19: 가솔린과 동일 (디젤이 있긴하나 극소수)
C20: SUV 하이브리드 (예: 투싼 HEV, 쏘렌토 HEV) | D20: - | E20: 14~18 | F20: 중량에 따라 차이 큼
C21: 대형 하이브리드 (예: 그랜저 HEV, G80 HEV) | D21: - | E21: 13~17 | F21: 전기 모터 도움으로 효율 개선
B23: 전기차 연료 전비
C24: 차량 종류 | D24: 평균 전비 (km/kWh) | E24: 1회 충전 주행거리 (km, 대략) | F24: 비고
C25: 소형 전기차 (예: 코나 EV, 니로 EV) | D25: 5.0~6.0 | E25: 350~450 | F25: 효율 우수
C26: 중형 전기차 (예: 아이오닉 6, 테슬라 모델 3) | D26: 5.0~6.5 | E26: 450~550 | F26: 공기역학적 효율 높음
C27: 대형 전기차 (예: 아이오닉 5, EV9, 모델 X) | D27: 4.0~5.0 | E27: 400~500 | F27: 무게 영향 큼
C28: 고성능 전기차 (예: 테슬라 퍼포먼스, 포르쉐 타이칸) | D28: 3.0~4.0 | E28: 300~400 | F28: 출력 중심 설계
B31: 연료별배출계수
C32: 연료 종류 | D32: 배출계수 (kgCO₂/ℓ) | E32: 출처
C33: 휘발유 (Gasoline) | D33: 2.271 | E33: 환경부 온실가스 배출계수 관리지침
C34: 경유 (Diesel) | D34: 2.641 | E34: 〃
C35: LPG (자동차용) | D35: 1.595 | E35: 〃
C36: CNG (압축천연가스) | D36: 2.175 (kgCO₂/Nm³) | E36: 〃
C37: 전기차 (Electric) | D37: 전력사용량 × 전력 배출계수(0.459 kgCO₂/kWh, ’23년 기준) | E37: KEPCO, 환경부
C39: 계산기준 | D39: 식 | E39: 비고
C40: 연료 사용량 기준 | D40: 배출량 = 연료사용량 × 배출계수 | E40: 가장 직접적
C41: 주행거리 기준 | D41: 배출량 = (주행거리 ÷ 연비) × 배출계수 | E41: 일반 차량 계산 시
C42: 전기차 | D42: 배출량 = 전력사용량 × 전력 배출계수 | E42: 간접배출(전력 생산단계)
